<?xml version='1.0' encoding='utf-8'?>
<robot name="ezgripper_stand_alone">
  <gazebo>
    <plugin name="gazebo_ros_control" filename="libgazebo_ros_control.so">
   </plugin>
  </gazebo>
  
  <link name="left_ezgripper_palm_link">
    <visual>
      <origin xyz="0 0 0" rpy="0 0 0" />
      <geometry>
        <mesh filename="meshes/ezgripper_gen2/SAKE_Palm_Dual_Gen2.stl" />
      </geometry>
    </visual>
    <collision>
      <origin xyz="0 0 0" rpy="0 0 0" />
      <geometry>
        <mesh filename="meshes/ezgripper_gen2/SAKE_Palm_Dual_Gen2.stl" />
      </geometry>
    </collision>
  </link>
  <joint name="left_ezgripper_connect" type="fixed">
    <origin xyz="0.0 0.0 0.0" rpy="0 0 0" />
    
    <parent link="world" />
    <child link="left_ezgripper_palm_link" />
    <axis xyz="0 0 0" />
    <limit effort="0" lower="-1.57075" upper="0.25" velocity="3.67" />
  </joint>
  <link name="left_ezgripper_finger_L1_1">
    <visual>
      <origin xyz="0 0 0" rpy="0 0 0" />
      <geometry>
        <mesh filename="meshes/ezgripper_gen2/SAKE_Finger_L1_Gen2.stl" />
      </geometry>
    </visual>
    <collision>
      <origin xyz="0 0 0" rpy="0 0 0" />
      <geometry>
        <mesh filename="meshes/ezgripper_gen2/SAKE_Finger_L1_Gen2.stl" />
      </geometry>
    </collision>
  </link>
  <link name="left_ezgripper_finger_L1_2">
    <visual>
      <origin xyz="0 0 0" rpy="0 0 0" />
      <geometry>
        <mesh filename="meshes/ezgripper_gen2/SAKE_Finger_L1_Gen2.stl" />
      </geometry>
    </visual>
    <collision>
      <origin xyz="0 0 0" rpy="0 0 0" />
      <geometry>
        <mesh filename="meshes/ezgripper_gen2/SAKE_Finger_L1_Gen2.stl" />
      </geometry>
    </collision>
  </link>
  <link name="left_ezgripper_finger_L2_1">
    <visual>
      <origin xyz="0 0 0" rpy="0 0 0" />
      <geometry>
        <mesh filename="meshes/ezgripper_gen2/SAKE_Finger_L2_Gen2.stl" />
      </geometry>
    </visual>
    <collision>
      <origin xyz="0 0 0" rpy="0 0 0" />
      <geometry>
        <mesh filename="meshes/ezgripper_gen2/SAKE_Finger_L2_Gen2.stl" />
      </geometry>
    </collision>
  </link>
  <link name="left_ezgripper_finger_L2_2">
    <visual>
      <origin xyz="0 0 0" rpy="0 0 0" />
      <geometry>
        <mesh filename="meshes/ezgripper_gen2/SAKE_Finger_L2_Gen2.stl" />
      </geometry>
    </visual>
    <collision>
      <origin xyz="0 0 0" rpy="0 0 0" />
      <geometry>
        <mesh filename="meshes/ezgripper_gen2/SAKE_Finger_L2_Gen2.stl" />
      </geometry>
    </collision>
  </link>
  <joint name="left_ezgripper_knuckle_palm_L1_1" type="revolute">
    <parent link="left_ezgripper_palm_link" />
    <child link="left_ezgripper_finger_L1_1" />
    <origin xyz="0.072569 0.03 0" rpy="-1.5708 0 1.57075" />
    <axis xyz="0 1 0" />
    <limit lower="0" upper="1.94" effort="1" velocity="3.67" />
  </joint>
  <joint name="left_ezgripper_knuckle_palm_L1_2" type="revolute">
    <parent link="left_ezgripper_palm_link" />
    <child link="left_ezgripper_finger_L1_2" />
    <origin xyz="0.072569 -0.03 0" rpy="1.5708 0 -1.57075" />
    <axis xyz="0 1 0" />
    <limit lower="0" upper="1.94" effort="1" velocity="3.67" />
    <mimic joint="left_ezgripper_knuckle_palm_L1_1" />
  </joint>
  <joint name="left_ezgripper_knuckle_L1_L2_1" type="revolute">
    <parent link="left_ezgripper_finger_L1_1" />
    <child link="left_ezgripper_finger_L2_1" />
    <origin xyz="0.052 0 0" rpy="0 0 0" />
    
    <axis xyz="0 1 0" />
    <limit lower="0" upper="1.94" effort="1" velocity="3.67" />
  </joint>
  <joint name="left_ezgripper_knuckle_L1_L2_2" type="revolute">
    <parent link="left_ezgripper_finger_L1_2" />
    <child link="left_ezgripper_finger_L2_2" />
    <origin xyz="0.052 0 0" rpy="0 0 0" />
    
    <axis xyz="0 1 0" />
    <limit lower="0" upper="1.94" effort="1" velocity="3.67" />
    <mimic joint="left_ezgripper_knuckle_L1_L2_1" />
  </joint>
  <link name="world" />
  </robot>