<robot name="chain_0">
  <link name="link_0">
    <inertial>
      <mass value="1.026"/>
      <inertia ixx="0.0103" ixy="0" ixz="0" iyy="0.0103" iyz="0" izz="0.0103"/>
    </inertial>
    <visual>
      <origin xyz="0 0 0" rpy="0 0 0"/>
      <geometry>
      <box size="0.226 0.112 0.063"/>
      </geometry>
      <material name="gray"><color rgba="0.7 0.7 0.7 1"/></material>
    </visual>
    <collision>
      <origin xyz="0 0 0" rpy="0 0 0"/>
      <geometry>
      <box size="0.226 0.112 0.063"/>
      </geometry>
    </collision>
  </link>
  <link name="link_1">
    <inertial>
      <mass value="1.599"/>
      <inertia ixx="0.0160" ixy="0" ixz="0" iyy="0.0160" iyz="0" izz="0.0160"/>
    </inertial>
    <visual>
      <origin xyz="0 0 0" rpy="0 0 0"/>
      <geometry>
      <cylinder radius="0.056" length="0.290"/>
      </geometry>
      <material name="gray"><color rgba="0.7 0.7 0.7 1"/></material>
    </visual>
    <collision>
      <origin xyz="0 0 0" rpy="0 0 0"/>
      <geometry>
      <cylinder radius="0.056" length="0.290"/>
      </geometry>
    </collision>
  </link>
  <link name="link_2">
    <inertial>
      <mass value="1.368"/>
      <inertia ixx="0.0137" ixy="0" ixz="0" iyy="0.0137" iyz="0" izz="0.0137"/>
    </inertial>
    <visual>
      <origin xyz="0 0 0" rpy="0 0 0"/>
      <geometry>
      <box size="0.245 0.089 0.055"/>
      </geometry>
      <material name="gray"><color rgba="0.7 0.7 0.7 1"/></material>
    </visual>
    <collision>
      <origin xyz="0 0 0" rpy="0 0 0"/>
      <geometry>
      <box size="0.245 0.089 0.055"/>
      </geometry>
    </collision>
  </link>
  <link name="link_3">
    <inertial>
      <mass value="0.910"/>
      <inertia ixx="0.0091" ixy="0" ixz="0" iyy="0.0091" iyz="0" izz="0.0091"/>
    </inertial>
    <visual>
      <origin xyz="0 0 0" rpy="0 0 0"/>
      <geometry>
      <cylinder radius="0.051" length="0.112"/>
      </geometry>
      <material name="gray"><color rgba="0.7 0.7 0.7 1"/></material>
    </visual>
    <collision>
      <origin xyz="0 0 0" rpy="0 0 0"/>
      <geometry>
      <cylinder radius="0.051" length="0.112"/>
      </geometry>
    </collision>
  </link>
  <joint name="joint_0" type="revolute">
    <parent link="link_0"/>
    <child link="link_1"/>
    <origin xyz="0.278 0.000 0.000" rpy="0.000 0.000 0.000"/>
    <axis xyz="-0.0451 0.6785 -0.7332"/>
    <limit lower="-3.1416" upper="3.1416" effort="5" velocity="5"/>
  </joint>
  <joint name="joint_1" type="revolute">
    <parent link="link_1"/>
    <child link="link_2"/>
    <origin xyz="0.287 0.000 0.000" rpy="0.000 0.000 0.000"/>
    <axis xyz="-0.7637 0.4177 -0.4922"/>
    <limit lower="-3.1416" upper="3.1416" effort="5" velocity="5"/>
  </joint>
  <joint name="joint_2" type="revolute">
    <parent link="link_2"/>
    <child link="link_3"/>
    <origin xyz="0.199 0.000 0.000" rpy="0.000 0.000 0.000"/>
    <axis xyz="-0.9401 0.3397 0.0271"/>
    <limit lower="-3.1416" upper="3.1416" effort="5" velocity="5"/>
  </joint>
</robot>
