<robot name="chain_4">
  <link name="link_0">
    <inertial>
      <mass value="1.419"/>
      <inertia ixx="0.0142" ixy="0" ixz="0" iyy="0.0142" iyz="0" izz="0.0142"/>
    </inertial>
    <visual>
      <origin xyz="0 0 0" rpy="0 0 0"/>
      <geometry>
      <box size="0.098 0.110 0.072"/>
      </geometry>
      <material name="gray"><color rgba="0.7 0.7 0.7 1"/></material>
    </visual>
    <collision>
      <origin xyz="0 0 0" rpy="0 0 0"/>
      <geometry>
      <box size="0.098 0.110 0.072"/>
      </geometry>
    </collision>
  </link>
  <link name="link_1">
    <inertial>
      <mass value="1.306"/>
      <inertia ixx="0.0131" ixy="0" ixz="0" iyy="0.0131" iyz="0" izz="0.0131"/>
    </inertial>
    <visual>
      <origin xyz="0 0 0" rpy="0 0 0"/>
      <geometry>
      <cylinder radius="0.066" length="0.171"/>
      </geometry>
      <material name="gray"><color rgba="0.7 0.7 0.7 1"/></material>
    </visual>
    <collision>
      <origin xyz="0 0 0" rpy="0 0 0"/>
      <geometry>
      <cylinder radius="0.066" length="0.171"/>
      </geometry>
    </collision>
  </link>
  <link name="link_2">
    <inertial>
      <mass value="0.853"/>
      <inertia ixx="0.0085" ixy="0" ixz="0" iyy="0.0085" iyz="0" izz="0.0085"/>
    </inertial>
    <visual>
      <origin xyz="0 0 0" rpy="0 0 0"/>
      <geometry>
      <box size="0.096 0.058 0.114"/>
      </geometry>
      <material name="gray"><color rgba="0.7 0.7 0.7 1"/></material>
    </visual>
    <collision>
      <origin xyz="0 0 0" rpy="0 0 0"/>
      <geometry>
      <box size="0.096 0.058 0.114"/>
      </geometry>
    </collision>
  </link>
  <link name="link_3">
    <inertial>
      <mass value="1.509"/>
      <inertia ixx="0.0151" ixy="0" ixz="0" iyy="0.0151" iyz="0" izz="0.0151"/>
    </inertial>
    <visual>
      <origin xyz="0 0 0" rpy="0 0 0"/>
      <geometry>
      <box size="0.224 0.089 0.052"/>
      </geometry>
      <material name="gray"><color rgba="0.7 0.7 0.7 1"/></material>
    </visual>
    <collision>
      <origin xyz="0 0 0" rpy="0 0 0"/>
      <geometry>
      <box size="0.224 0.089 0.052"/>
      </geometry>
    </collision>
  </link>
  <joint name="joint_0" type="revolute">
    <parent link="link_0"/>
    <child link="link_1"/>
    <origin xyz="0.155 0.000 0.000" rpy="0.000 0.000 0.000"/>
    <axis xyz="-0.5573 0.7165 0.4195"/>
    <limit lower="-3.1416" upper="3.1416" effort="5" velocity="5"/>
  </joint>
  <joint name="joint_1" type="revolute">
    <parent link="link_1"/>
    <child link="link_2"/>
    <origin xyz="0.153 0.000 0.000" rpy="0.000 0.000 0.000"/>
    <axis xyz="0.5937 -0.6285 0.5024"/>
    <limit lower="-3.1416" upper="3.1416" effort="5" velocity="5"/>
  </joint>
  <joint name="joint_2" type="revolute">
    <parent link="link_2"/>
    <child link="link_3"/>
    <origin xyz="0.180 0.000 0.000" rpy="0.000 0.000 0.000"/>
    <axis xyz="0.1059 0.7767 0.6208"/>
    <limit lower="-3.1416" upper="3.1416" effort="5" velocity="5"/>
  </joint>
</robot>
