<robot name="chain_2">
  <link name="link_0">
    <inertial>
      <mass value="1.842"/>
      <inertia ixx="0.0184" ixy="0" ixz="0" iyy="0.0184" iyz="0" izz="0.0184"/>
    </inertial>
    <visual>
      <origin xyz="0 0 0" rpy="0 0 0"/>
      <geometry>
      <cylinder radius="0.069" length="0.157"/>
      </geometry>
      <material name="gray"><color rgba="0.7 0.7 0.7 1"/></material>
    </visual>
    <collision>
      <origin xyz="0 0 0" rpy="0 0 0"/>
      <geometry>
      <cylinder radius="0.069" length="0.157"/>
      </geometry>
    </collision>
  </link>
  <link name="link_1">
    <inertial>
      <mass value="0.654"/>
      <inertia ixx="0.0065" ixy="0" ixz="0" iyy="0.0065" iyz="0" izz="0.0065"/>
    </inertial>
    <visual>
      <origin xyz="0 0 0" rpy="0 0 0"/>
      <geometry>
      <box size="0.234 0.093 0.046"/>
      </geometry>
      <material name="gray"><color rgba="0.7 0.7 0.7 1"/></material>
    </visual>
    <collision>
      <origin xyz="0 0 0" rpy="0 0 0"/>
      <geometry>
      <box size="0.234 0.093 0.046"/>
      </geometry>
    </collision>
  </link>
  <link name="link_2">
    <inertial>
      <mass value="0.514"/>
      <inertia ixx="0.0051" ixy="0" ixz="0" iyy="0.0051" iyz="0" izz="0.0051"/>
    </inertial>
    <visual>
      <origin xyz="0 0 0" rpy="0 0 0"/>
      <geometry>
      <box size="0.234 0.087 0.063"/>
      </geometry>
      <material name="gray"><color rgba="0.7 0.7 0.7 1"/></material>
    </visual>
    <collision>
      <origin xyz="0 0 0" rpy="0 0 0"/>
      <geometry>
      <box size="0.234 0.087 0.063"/>
      </geometry>
    </collision>
  </link>
  <link name="link_3">
    <inertial>
      <mass value="1.651"/>
      <inertia ixx="0.0165" ixy="0" ixz="0" iyy="0.0165" iyz="0" izz="0.0165"/>
    </inertial>
    <visual>
      <origin xyz="0 0 0" rpy="0 0 0"/>
      <geometry>
      <box size="0.140 0.040 0.114"/>
      </geometry>
      <material name="gray"><color rgba="0.7 0.7 0.7 1"/></material>
    </visual>
    <collision>
      <origin xyz="0 0 0" rpy="0 0 0"/>
      <geometry>
      <box size="0.140 0.040 0.114"/>
      </geometry>
    </collision>
  </link>
  <joint name="joint_0" type="revolute">
    <parent link="link_0"/>
    <child link="link_1"/>
    <origin xyz="0.215 0.000 0.000" rpy="0.000 0.000 0.000"/>
    <axis xyz="0.9067 0.4216 0.0114"/>
    <limit lower="-3.1416" upper="3.1416" effort="5" velocity="5"/>
  </joint>
  <joint name="joint_1" type="revolute">
    <parent link="link_1"/>
    <child link="link_2"/>
    <origin xyz="0.254 0.000 0.000" rpy="0.000 0.000 0.000"/>
    <axis xyz="-0.6101 0.5999 -0.5176"/>
    <limit lower="-3.1416" upper="3.1416" effort="5" velocity="5"/>
  </joint>
  <joint name="joint_2" type="revolute">
    <parent link="link_2"/>
    <child link="link_3"/>
    <origin xyz="0.207 0.000 0.000" rpy="0.000 0.000 0.000"/>
    <axis xyz="-0.5216 0.8339 -0.1806"/>
    <limit lower="-3.1416" upper="3.1416" effort="5" velocity="5"/>
  </joint>
</robot>
