<robot name="chain_1">
  <link name="link_0">
    <inertial>
      <mass value="1.876"/>
      <inertia ixx="0.0188" ixy="0" ixz="0" iyy="0.0188" iyz="0" izz="0.0188"/>
    </inertial>
    <visual>
      <origin xyz="0 0 0" rpy="0 0 0"/>
      <geometry>
      <box size="0.128 0.102 0.089"/>
      </geometry>
      <material name="gray"><color rgba="0.7 0.7 0.7 1"/></material>
    </visual>
    <collision>
      <origin xyz="0 0 0" rpy="0 0 0"/>
      <geometry>
      <box size="0.128 0.102 0.089"/>
      </geometry>
    </collision>
  </link>
  <link name="link_1">
    <inertial>
      <mass value="1.952"/>
      <inertia ixx="0.0195" ixy="0" ixz="0" iyy="0.0195" iyz="0" izz="0.0195"/>
    </inertial>
    <visual>
      <origin xyz="0 0 0" rpy="0 0 0"/>
      <geometry>
      <cylinder radius="0.061" length="0.169"/>
      </geometry>
      <material name="gray"><color rgba="0.7 0.7 0.7 1"/></material>
    </visual>
    <collision>
      <origin xyz="0 0 0" rpy="0 0 0"/>
      <geometry>
      <cylinder radius="0.061" length="0.169"/>
      </geometry>
    </collision>
  </link>
  <link name="link_2">
    <inertial>
      <mass value="1.937"/>
      <inertia ixx="0.0194" ixy="0" ixz="0" iyy="0.0194" iyz="0" izz="0.0194"/>
    </inertial>
    <visual>
      <origin xyz="0 0 0" rpy="0 0 0"/>
      <geometry>
      <cylinder radius="0.037" length="0.194"/>
      </geometry>
      <material name="gray"><color rgba="0.7 0.7 0.7 1"/></material>
    </visual>
    <collision>
      <origin xyz="0 0 0" rpy="0 0 0"/>
      <geometry>
      <cylinder radius="0.037" length="0.194"/>
      </geometry>
    </collision>
  </link>
  <link name="link_3">
    <inertial>
      <mass value="1.548"/>
      <inertia ixx="0.0155" ixy="0" ixz="0" iyy="0.0155" iyz="0" izz="0.0155"/>
    </inertial>
    <visual>
      <origin xyz="0 0 0" rpy="0 0 0"/>
      <geometry>
      <box size="0.102 0.066 0.070"/>
      </geometry>
      <material name="gray"><color rgba="0.7 0.7 0.7 1"/></material>
    </visual>
    <collision>
      <origin xyz="0 0 0" rpy="0 0 0"/>
      <geometry>
      <box size="0.102 0.066 0.070"/>
      </geometry>
    </collision>
  </link>
  <joint name="joint_0" type="revolute">
    <parent link="link_0"/>
    <child link="link_1"/>
    <origin xyz="0.169 0.000 0.000" rpy="0.000 0.000 0.000"/>
    <axis xyz="-0.4258 0.8540 0.2992"/>
    <limit lower="-3.1416" upper="3.1416" effort="5" velocity="5"/>
  </joint>
  <joint name="joint_1" type="revolute">
    <parent link="link_1"/>
    <child link="link_2"/>
    <origin xyz="0.201 0.000 0.000" rpy="0.000 0.000 0.000"/>
    <axis xyz="0.8183 0.2342 -0.5249"/>
    <limit lower="-3.1416" upper="3.1416" effort="5" velocity="5"/>
  </joint>
  <joint name="joint_2" type="revolute">
    <parent link="link_2"/>
    <child link="link_3"/>
    <origin xyz="0.168 0.000 0.000" rpy="0.000 0.000 0.000"/>
    <axis xyz="0.7731 -0.3857 -0.5035"/>
    <limit lower="-3.1416" upper="3.1416" effort="5" velocity="5"/>
  </joint>
</robot>
